    else engine.raw_connection()

         ^^^^^^^^^^^^^^^^^^^^^^^

  File "/opt/venv/lib/python3.11/site-packages/sqlalchemy/engine/base.py", line 3245, in raw_connection

    return self._wrap_pool_connect(self.pool.connect, _connection)

           ^^^^^^^^^^^^^^^^^^^^^^^^^^^^^^^^^^^^^^^^^^^^^^^^^^^^^^^

  File "/opt/venv/lib/python3.11/site-packages/sqlalchemy/engine/base.py", line 3215, in _wrap_pool_connect

    Connection._handle_dbapi_exception_noconnection(

  File "/opt/venv/lib/python3.11/site-packages/sqlalchemy/engine/base.py", line 2069, in _handle_dbapi_exception_noconnection

    util.raise_(

  File "/opt/venv/lib/python3.11/site-packages/sqlalchemy/util/compat.py", line 207, in raise_

    raise exception

  File "/opt/venv/lib/python3.11/site-packages/sqlalchemy/engine/base.py", line 3212, in _wrap_pool_connect

    return fn()

           ^^^^

  File "/opt/venv/lib/python3.11/site-packages/sqlalchemy/pool/base.py", line 307, in connect

    return _ConnectionFairy._checkout(self)

           ^^^^^^^^^^^^^^^^^^^^^^^^^^^^^^^^

  File "/opt/venv/lib/python3.11/site-packages/sqlalchemy/pool/base.py", line 767, in _checkout

    fairy = _ConnectionRecord.checkout(pool)

            ^^^^^^^^^^^^^^^^^^^^^^^^^^^^^^^^

  File "/opt/venv/lib/python3.11/site-packages/sqlalchemy/pool/base.py", line 425, in checkout

    rec = pool._do_get()

          ^^^^^^^^^^^^^^

  File "/opt/venv/lib/python3.11/site-packages/sqlalchemy/pool/impl.py", line 256, in _do_get

    return self._create_connection()

           ^^^^^^^^^^^^^^^^^^^^^^^^^

  File "/opt/venv/lib/python3.11/site-packages/sqlalchemy/pool/base.py", line 253, in _create_connection

    return _ConnectionRecord(self)

           ^^^^^^^^^^^^^^^^^^^^^^^

  File "/opt/venv/lib/python3.11/site-packages/sqlalchemy/pool/base.py", line 368, in __init__

    self.__connect()

  File "/opt/venv/lib/python3.11/site-packages/sqlalchemy/pool/base.py", line 610, in __connect

    with util.safe_reraise():

  File "/opt/venv/lib/python3.11/site-packages/sqlalchemy/util/langhelpers.py", line 70, in __exit__

    compat.raise_(

  File "/opt/venv/lib/python3.11/site-packages/sqlalchemy/util/compat.py", line 207, in raise_

    raise exception

  File "/opt/venv/lib/python3.11/site-packages/sqlalchemy/pool/base.py", line 605, in __connect

    connection = pool._invoke_creator(self)

                 ^^^^^^^^^^^^^^^^^^^^^^^^^^

  File "/opt/venv/lib/python3.11/site-packages/sqlalchemy/engine/create.py", line 578, in connect

    return dialect.connect(*cargs, **cparams)

           ^^^^^^^^^^^^^^^^^^^^^^^^^^^^^^^^^^

  File "/opt/venv/lib/python3.11/site-packages/sqlalchemy/engine/default.py", line 584, in connect

    return self.dbapi.connect(*cargs, **cparams)

           ^^^^^^^^^^^^^^^^^^^^^^^^^^^^^^^^^^^^^

sqlalchemy.exc.OperationalError: (sqlite3.OperationalError) unable to open database file

(Background on this error at: https://sqlalche.me/e/14/e3q8)